Workbook

Sheet annotation
A1: Name | B1: Extension | C1: Present
A2: osu_View_Syllabi_0aca0bce.pdf | B2: .pdf | C2: =IF(COUNTIF(Sheet1!D:D, A2)>0, "✓", "") -> ✓
A3: ufl_Contracts-Arnow-Richman-Syll-Part-2.Reading.S23_50ee90a2.pdf | B3: .pdf | C3: =IF(COUNTIF(Sheet1!D:D, A3)>0, "✓", "") -> ✓
A4: ufl_ENG3122-S206-30349-Ray_15c2759e.pdf | B4: .pdf | C4: =IF(COUNTIF(Sheet1!D:D, A4)>0, "✓", "") -> ✓
A5: ufl_eoc6934_spring2025_215e781c.pdf | B5: .pdf | C5: =IF(COUNTIF(Sheet1!D:D, A5)>0, "✓", "") -> ✓
A6: ufl_GEY4001_2G10_Spring2026_d90d157e.pdf | B6: .pdf | C6: =IF(COUNTIF(Sheet1!D:D, A6)>0, "✓", "") -> ✓
A7: ufl_JOU3101-Reporting-Foley-Spring-2025_bdb9cdd7.pdf | B7: .pdf | C7: =IF(COUNTIF(Sheet1!D:D, A7)>0, "✓", "") -> ✓
A8: ufl_JPW4130_F24_39da2d7b.pdf | B8: .pdf | C8: =IF(COUNTIF(Sheet1!D:D, A8)>0, "✓", "") -> ✓
A9: ufl_KarmakarBikram_syllabusSTA7934-_fall2023-1_26fce759.pdf | B9: .pdf | C9: =IF(COUNTIF(Sheet1!D:D, A9)>0, "✓", "") -> ✓
A10: ufl_LAE-6947-8MB2-28596-Bryant_03dbd900.pdf | B10: .pdf | C10: =IF(COUNTIF(Sheet1!D:D, A10)>0, "✓", "") -> ✓
A11: ufl_CWR3201-Syllabus-Fall-2025_1a7780ea.pdf | B11: .pdf | C11: =IF(COUNTIF(Sheet1!D:D, A11)>0, "✓", "") -> ✓
A12: ufl_Daniels_STA7249-spring-i2020_c15107cd.pdf | B12: .pdf | C12: =IF(COUNTIF(Sheet1!D:D, A12)>0, "✓", "") -> ✓
A13: ufl_ECO3713_Rojas_Spr22_0089f8e1.pdf | B13: .pdf | C13: =IF(COUNTIF(Sheet1!D:D, A13)>0, "✓", "") -> ✓
... A103: annotations.xlsx | B103: .xlsx | C103: =IF(COUNTIF(Sheet1!D:D, A103)>0, "✓", "")

Sheet Sheet1
A1: title | B1: first | C1: last | D1: file | E1: file_path (remove)
A2: Making and Doing Deals: Contracts in Context | C2: Epstein | D2: =_xlfn.TEXTAFTER(E2,"\Syllabi\annotation\") -> ufl_Contracts-Arnow-Richman-Syll-Part-2.Reading.S23_50ee90a2.pdf | E2: C:\Users\adaml\OneDrive\Syllabi\annotation\ufl_Contracts-Arnow-Richman-Syll-Part-2.Reading.S23_50ee90a2.pdf
A3: Restatement Second of Contracts | D3: =_xlfn.TEXTAFTER(E3,"\Syllabi\annotation\") -> ufl_Contracts-Arnow-Richman-Syll-Part-2.Reading.S23_50ee90a2.pdf | E3: C:\Users\adaml\OneDrive\Syllabi\annotation\ufl_Contracts-Arnow-Richman-Syll-Part-2.Reading.S23_50ee90a2.pdf
A4: Uniform Commercial Code | D4: =_xlfn.TEXTAFTER(E4,"\Syllabi\annotation\") -> ufl_Contracts-Arnow-Richman-Syll-Part-2.Reading.S23_50ee90a2.pdf | E4: C:\Users\adaml\OneDrive\Syllabi\annotation\ufl_Contracts-Arnow-Richman-Syll-Part-2.Reading.S23_50ee90a2.pdf
A5: The Bell Jar | B5: Sylvia | C5: Plath | D5: =_xlfn.TEXTAFTER(E5,"\Syllabi\annotation\") -> ufl_LAE-6947-8MB2-28596-Bryant_03dbd900.pdf | E5: C:\Users\adaml\OneDrive\Syllabi\annotation\ufl_LAE-6947-8MB2-28596-Bryant_03dbd900.pdf
A6: Tender Buttons | B6: Gertrude | C6: Stein | D6: =_xlfn.TEXTAFTER(E6,"\Syllabi\annotation\") -> ufl_LAE-6947-8MB2-28596-Bryant_03dbd900.pdf | E6: C:\Users\adaml\OneDrive\Syllabi\annotation\ufl_LAE-6947-8MB2-28596-Bryant_03dbd900.pdf
A7: Mrs. Dalloway | B7: Virginia | C7: Woolf | D7: =_xlfn.TEXTAFTER(E7,"\Syllabi\annotation\") -> ufl_LAE-6947-8MB2-28596-Bryant_03dbd900.pdf | E7: C:\Users\adaml\OneDrive\Syllabi\annotation\ufl_LAE-6947-8MB2-28596-Bryant_03dbd900.pdf
A8: Best Poems | B8: Stevie | C8: Smith | D8: =_xlfn.TEXTAFTER(E8,"\Syllabi\annotation\") -> ufl_LAE-6947-8MB2-28596-Bryant_03dbd900.pdf | E8: C:\Users\adaml\OneDrive\Syllabi\annotation\ufl_LAE-6947-8MB2-28596-Bryant_03dbd900.pdf
A9: Maud Martha | B9: Gwendolyn | C9: Brooks | D9: =_xlfn.TEXTAFTER(E9,"\Syllabi\annotation\") -> ufl_LAE-6947-8MB2-28596-Bryant_03dbd900.pdf | E9: C:\Users\adaml\OneDrive\Syllabi\annotation\ufl_LAE-6947-8MB2-28596-Bryant_03dbd900.pdf
A10: Ariel | B10: Sylvia | C10: Plath | D10: =_xlfn.TEXTAFTER(E10,"\Syllabi\annotation\") -> ufl_LAE-6947-8MB2-28596-Bryant_03dbd900.pdf | E10: C:\Users\adaml\OneDrive\Syllabi\annotation\ufl_LAE-6947-8MB2-28596-Bryant_03dbd900.pdf
A11: The Bloody Chamber | B11: Angela | C11: Carter | D11: =_xlfn.TEXTAFTER(E11,"\Syllabi\annotation\") -> ufl_LAE-6947-8MB2-28596-Bryant_03dbd900.pdf | E11: C:\Users\adaml\OneDrive\Syllabi\annotation\ufl_LAE-6947-8MB2-28596-Bryant_03dbd900.pdf
A12: Fun Home | B12: Alison | C12: Bechdel | D12: =_xlfn.TEXTAFTER(E12,"\Syllabi\annotation\") -> ufl_LAE-6947-8MB2-28596-Bryant_03dbd900.pdf | E12: C:\Users\adaml\OneDrive\Syllabi\annotation\ufl_LAE-6947-8MB2-28596-Bryant_03dbd900.pdf
A13: Thomas and Beulah | B13: Rita | C13: Dove | D13: =_xlfn.TEXTAFTER(E13,"\Syllabi\annotation\") -> ufl_LAE-6947-8MB2-28596-Bryant_03dbd900.pdf | E13: C:\Users\adaml\OneDrive\Syllabi\annotation\ufl_LAE-6947-8MB2-28596-Bryant_03dbd900.pdf
A14: The Penelopiad | B14: Margaret | C14: Atwood | D14: =_xlfn.TEXTAFTER(E14,"\Syllabi\annotation\") -> ufl_LAE-6947-8MB2-28596-Bryant_03dbd900.pdf | E14: C:\Users\adaml\OneDrive\Syllabi\annotation\ufl_LAE-6947-8MB2-28596-Bryant_03dbd900.pdf
A15: Marvelous Things Overheard | B15: Ange | C15: Mlinko | D15: =_xlfn.TEXTAFTER(E15,"\Syllabi\annotation\") -> ufl_LAE-6947-8MB2-28596-Bryant_03dbd900.pdf | E15: C:\Users\adaml\OneDrive\Syllabi\annotation\ufl_LAE-6947-8MB2-28596-Bryant_03dbd900.pdf
A16: None | D16: =_xlfn.TEXTAFTER(E16,"\Syllabi\annotation\") -> osu_View_Syllabi_0aca0bce.pdf | E16: C:\Users\adaml\OneDrive\Syllabi\annotation\osu_View_Syllabi_0aca0bce.pdf
A17: None | D17: =_xlfn.TEXTAFTER(E17,"\Syllabi\annotation\") -> ufl_KarmakarBikram_syllabusSTA7934-_fall2023-1_26fce759.pdf | E17: C:\Users\adaml\OneDrive\Syllabi\annotation\ufl_KarmakarBikram_syllabusSTA7934-_fall2023-1_26fce759.pdf
A18: Yume jūya | B18: Natsume | C18: Sōseki | D18: =_xlfn.TEXTAFTER(E18,"\Syllabi\annotation\") -> ufl_JPW4130_F24_39da2d7b.pdf | E18: C:\Users\adaml\OneDrive\Syllabi\annotation\ufl_JPW4130_F24_39da2d7b.pdf
A19: Tongari yaki no seisui | B19: Murakami | C19: Haruki | D19: =_xlfn.TEXTAFTER(E19,"\Syllabi\annotation\") -> ufl_JPW4130_F24_39da2d7b.pdf | E19: C:\Users\adaml\OneDrive\Syllabi\annotation\ufl_JPW4130_F24_39da2d7b.pdf
A20: Konbini Ningen | B20: Murata | C20: Sayaka | D20: =_xlfn.TEXTAFTER(E20,"\Syllabi\annotation\") -> ufl_JPW4130_F24_39da2d7b.pdf | E20: C:\Users\adaml\OneDrive\Syllabi\annotation\ufl_JPW4130_F24_39da2d7b.pdf
A21: The Great Gatsby | B21: Scott | C21: Fitzgerald | D21: =_xlfn.TEXTAFTER(E21,"\Syllabi\annotation\") -> ufl_JPW4130_F24_39da2d7b.pdf | E21: C:\Users\adaml\OneDrive\Syllabi\annotation\ufl_JPW4130_F24_39da2d7b.pdf
A22: What We Talk About When We Talk About Love | B22: Raymond | C22: Carter | D22: =_xlfn.TEXTAFTER(E22,"\Syllabi\annotation\") -> ufl_JPW4130_F24_39da2d7b.pdf | E22: C:\Users\adaml\OneDrive\Syllabi\annotation\ufl_JPW4130_F24_39da2d7b.pdf
A23: Install | B23: Wataya | C23: Risa | D23: =_xlfn.TEXTAFTER(E23,"\Syllabi\annotation\") -> ufl_JPW4130_F24_39da2d7b.pdf | E23: C:\Users\adaml\OneDrive\Syllabi\annotation\ufl_JPW4130_F24_39da2d7b.pdf
A24: Growing Down | B24: Shimizu | C24: Yoshinari | D24: =_xlfn.TEXTAFTER(E24,"\Syllabi\annotation\") -> ufl_JPW4130_F24_39da2d7b.pdf | E24: C:\Users\adaml\OneDrive\Syllabi\annotation\ufl_JPW4130_F24_39da2d7b.pdf
A25: Monogatari shōhiron | B25: Ōtsuka | C25: Eiji | D25: =_xlfn.TEXTAFTER(E25,"\Syllabi\annotation\") -> ufl_JPW4130_F24_39da2d7b.pdf | E25: C:\Users\adaml\OneDrive\Syllabi\annotation\ufl_JPW4130_F24_39da2d7b.pdf
A26: How I Got That Story | C26: Foley | D26: =_xlfn.TEXTAFTER(E26,"\Syllabi\annotation\") -> ufl_JOU3101-Reporting-Foley-Spring-2025_bdb9cdd7.pdf | E26: C:\Users\adaml\OneDrive\Syllabi\annotation\ufl_JOU3101-Reporting-Foley-Spring-2025_bdb9cdd7.pdf
A27: AP Stylebook | D27: =_xlfn.TEXTAFTER(E27,"\Syllabi\annotation\") -> ufl_JOU3101-Reporting-Foley-Spring-2025_bdb9cdd7.pdf | E27: C:\Users\adaml\OneDrive\Syllabi\annotation\ufl_JOU3101-Reporting-Foley-Spring-2025_bdb9cdd7.pdf
A28: Inside Reporting | C28: Harrower | D28: =_xlfn.TEXTAFTER(E28,"\Syllabi\annotation\") -> ufl_JOU3101-Reporting-Foley-Spring-2025_bdb9cdd7.pdf | E28: C:\Users\adaml\OneDrive\Syllabi\annotation\ufl_JOU3101-Reporting-Foley-Spring-2025_bdb9cdd7.pdf
A29: When Words Collide | C29: Kessler-McDonald | D29: =_xlfn.TEXTAFTER(E29,"\Syllabi\annotation\") -> ufl_JOU3101-Reporting-Foley-Spring-2025_bdb9cdd7.pdf | E29: C:\Users\adaml\OneDrive\Syllabi\annotation\ufl_JOU3101-Reporting-Foley-Spring-2025_bdb9cdd7.pdf
A30: Webster's New World College Dictionary | D30: =_xlfn.TEXTAFTER(E30,"\Syllabi\annotation\") -> ufl_JOU3101-Reporting-Foley-Spring-2025_bdb9cdd7.pdf | E30: C:\Users\adaml\OneDrive\Syllabi\annotation\ufl_JOU3101-Reporting-Foley-Spring-2025_bdb9cdd7.pdf
A31: Introduction to Aging: A Positive, Interdisciplinary Approach | C31: Sugar | D31: =_xlfn.TEXTAFTER(E31,"\Syllabi\annotation\") -> ufl_GEY4001_2G10_Spring2026_d90d157e.pdf | E31: C:\Users\adaml\OneDrive\Syllabi\annotation\ufl_GEY4001_2G10_Spring2026_d90d157e.pdf
A32: Coastal Storms: Processes and Impacts | B32: Paolo | C32: Ciavola | D32: =_xlfn.TEXTAFTER(E32,"\Syllabi\annotation\") -> ufl_eoc6934_spring2025_215e781c.pdf | E32: C:\Users\adaml\OneDrive\Syllabi\annotation\ufl_eoc6934_spring2025_215e781c.pdf
A33: The Principles of Scientific Management | C33: Taylor | D33: =_xlfn.TEXTAFTER(E33,"\Syllabi\annotation\") -> ufl_ENG3122-S206-30349-Ray_15c2759e.pdf | E33: C:\Users\adaml\OneDrive\Syllabi\annotation\ufl_ENG3122-S206-30349-Ray_15c2759e.pdf
A34: The Genius of the System | C34: Schatz | D34: =_xlfn.TEXTAFTER(E34,"\Syllabi\annotation\") -> ufl_ENG3122-S206-30349-Ray_15c2759e.pdf | E34: C:\Users\adaml\OneDrive\Syllabi\annotation\ufl_ENG3122-S206-30349-Ray_15c2759e.pdf
A35: Hitler: The Führer and the People | C35: Stern | D35: =_xlfn.TEXTAFTER(E35,"\Syllabi\annotation\") -> ufl_ENG3122-S206-30349-Ray_15c2759e.pdf | E35: C:\Users\adaml\OneDrive\Syllabi\annotation\ufl_ENG3122-S206-30349-Ray_15c2759e.pdf
A36: The Making of Casablance | C36: Harmetz | D36: =_xlfn.TEXTAFTER(E36,"\Syllabi\annotation\") -> ufl_ENG3122-S206-30349-Ray_15c2759e.pdf | E36: C:\Users\adaml\OneDrive\Syllabi\annotation\ufl_ENG3122-S206-30349-Ray_15c2759e.pdf
A37: Cahiers du Cinéma: The 1950s | C37: Hillier | D37: =_xlfn.TEXTAFTER(E37,"\Syllabi\annotation\") -> ufl_ENG3122-S206-30349-Ray_15c2759e.pdf | E37: C:\Users\adaml\OneDrive\Syllabi\annotation\ufl_ENG3122-S206-30349-Ray_15c2759e.pdf
A38: Henry Ford: Mass Production, Modernism and Design | C38: Batchelor | D38: =_xlfn.TEXTAFTER(E38,"\Syllabi\annotation\") -> ufl_ENG3122-S206-30349-Ray_15c2759e.pdf | E38: C:\Users\adaml\OneDrive\Syllabi\annotation\ufl_ENG3122-S206-30349-Ray_15c2759e.pdf
A39: Brecht on Theatre | C39: Brecht | D39: =_xlfn.TEXTAFTER(E39,"\Syllabi\annotation\") -> ufl_ENG3122-S206-30349-Ray_15c2759e.pdf | E39: C:\Users\adaml\OneDrive\Syllabi\annotation\ufl_ENG3122-S206-30349-Ray_15c2759e.pdf
A40: Jean Renoir | C40: Braudy | D40: =_xlfn.TEXTAFTER(E40,"\Syllabi\annotation\") -> ufl_ENG3122-S206-30349-Ray_15c2759e.pdf | E40: C:\Users\adaml\OneDrive\Syllabi\annotation\ufl_ENG3122-S206-30349-Ray_15c2759e.pdf
...
